[2024-07-24 04:00:09,632] INFO - prefect.clean_log_file | 
Limpeza do arquivo de log local logs.txt realizada com sucesso.
[2024-07-24 04:00:09,701] INFO - prefect.CloudTaskRunner | Task 'clean_log_file': Finished task run for task with final state: 'Success'
[2024-07-24 04:00:09,704] INFO - prefect.CloudTaskRunner | Task 'clean_log_file': Finished task run for task with final state: 'Success'
[2024-07-24 04:00:09,754] INFO - prefect.CloudTaskRunner | Task 'run_dbt': Starting task run...
[2024-07-24 04:00:09,758] INFO - prefect.CloudTaskRunner | Task 'run_dbt': Starting task run...
[2024-07-24 04:00:13,250] INFO - prefect.run_dbt | 
Falha na transformação (DBT):  CompletedProcess(args=['dbt', 'run', '--vars', 'database: None'], returncode=2, stdout='\x1b[0m07:00:11  Running with dbt=1.8.4\n\x1b[0m07:00:11  Registered adapter: postgres=1.8.2\n\x1b[0m07:00:11  [\x1b[33mWARNING\x1b[0m]: Configuration paths exist in your dbt_project.yml file which do not apply to any resources.\nThere are 2 unused configuration paths:\n- models.desafio_data_eng.marts\n- seeds.desafio_data_eng\n\x1b[0m07:00:11  Found 3 models, 2 data tests, 1 source, 415 macros\n\x1b[0m07:00:11  \n\x1b[0m07:00:11  \n\x1b[0m07:00:11  Finished running  in 0 hours 0 minutes and 0.02 seconds (0.02s).\n\x1b[0m07:00:11  Encountered an error:\nRuntime Error\n  ERROR: Cross-db references not allowed in postgres (None vs prefect_server)\n', stderr='') 
[2024-07-24 04:00:13,251] INFO - prefect.CloudTaskRunner | FAIL signal raised: FAIL(None)
[2024-07-24 04:00:13,262] INFO - prefect.run_dbt | 
Falha na transformação (DBT):  CompletedProcess(args=['dbt', 'run', '--vars', 'database: None'], returncode=2, stdout='\x1b[0m07:00:11  Running with dbt=1.8.4\n\x1b[0m07:00:11  Registered adapter: postgres=1.8.2\n\x1b[0m07:00:11  [\x1b[33mWARNING\x1b[0m]: Configuration paths exist in your dbt_project.yml file which do not apply to any resources.\nThere are 2 unused configuration paths:\n- models.desafio_data_eng.marts\n- seeds.desafio_data_eng\n\x1b[0m07:00:11  Found 3 models, 2 data tests, 1 source, 415 macros\n\x1b[0m07:00:11  \n\x1b[0m07:00:11  \n\x1b[0m07:00:11  Finished running  in 0 hours 0 minutes and 0.03 seconds (0.03s).\n\x1b[0m07:00:11  Encountered an error:\nRuntime Error\n  ERROR: Cross-db references not allowed in postgres (None vs prefect_server)\n', stderr='') 
[2024-07-24 04:00:13,262] INFO - prefect.CloudTaskRunner | FAIL signal raised: FAIL(None)
[2024-07-24 04:00:13,288] INFO - prefect.CloudTaskRunner | Task 'run_dbt': Finished task run for task with final state: 'Failed'
[2024-07-24 04:00:13,294] INFO - prefect.CloudTaskRunner | Task 'run_dbt': Finished task run for task with final state: 'Failed'
[2024-07-24 04:00:13,319] INFO - prefect.CloudTaskRunner | Task 'upload_logs_to_database': Starting task run...
[2024-07-24 04:00:13,320] INFO - prefect.CloudTaskRunner | Task 'upload_logs_to_database': Starting task run...
[2024-07-24 04:00:13,365] INFO - prefect.upload_logs_to_database | 
Falha ao conectar com o PostgreSQL: connection to server on socket "/var/run/postgresql/.s.PGSQL.5432" failed: No such file or directory
	Is the server running locally and accepting connections on that socket?

[2024-07-24 04:00:13,365] INFO - prefect.upload_logs_to_database | 
Falha ao conectar com o PostgreSQL: connection to server on socket "/var/run/postgresql/.s.PGSQL.5432" failed: No such file or directory
	Is the server running locally and accepting connections on that socket?

[2024-07-24 04:00:13,365] INFO - prefect.CloudTaskRunner | FAIL signal raised: FAIL(None)
[2024-07-24 04:00:13,365] INFO - prefect.CloudTaskRunner | FAIL signal raised: FAIL(None)
[2024-07-24 04:00:13,396] INFO - prefect.CloudTaskRunner | Task 'upload_logs_to_database': Finished task run for task with final state: 'Failed'
[2024-07-24 04:00:13,399] INFO - prefect.CloudTaskRunner | Task 'upload_logs_to_database': Finished task run for task with final state: 'Failed'
[2024-07-24 04:00:13,416] INFO - prefect.CloudFlowRunner | Flow run FAILED: some reference tasks failed.
[2024-07-24 04:00:13,417] INFO - prefect.CloudFlowRunner | Flow run FAILED: some reference tasks failed.
