[2024-07-24 17:21:16,213] INFO - prefect.clean_log_file | 
 <> Limpeza do arquivo de log local logs.txt realizada com sucesso.
[2024-07-24 17:21:16,256] INFO - prefect.CloudTaskRunner | Task 'clean_log_file': Finished task run for task with final state: 'Success'
[2024-07-24 17:21:16,281] INFO - prefect.CloudTaskRunner | Task 'run_dbt': Starting task run...
[2024-07-24 17:21:20,778] INFO - prefect.run_dbt | 
 <> Falha na transformação (DBT):  CompletedProcess(args=['dbt', 'run', '--vars', 'database: None'], returncode=2, stdout='\x1b[0m20:21:17  Running with dbt=1.8.4\n\x1b[0m20:21:17  Registered adapter: postgres=1.8.2\n\x1b[0m20:21:17  Unable to do partial parsing because config vars, config profile, or config target have changed\n\x1b[0m20:21:19  [\x1b[33mWARNING\x1b[0m]: Deprecated functionality\nThe `tests` config has been renamed to `data_tests`. Please see\nhttps://docs.getdbt.com/docs/build/data-tests#new-data_tests-syntax for more\ninformation.\n\x1b[0m20:21:19  [\x1b[33mWARNING\x1b[0m]: Configuration paths exist in your dbt_project.yml file which do not apply to any resources.\nThere are 2 unused configuration paths:\n- models.desafio_data_eng.marts\n- seeds.desafio_data_eng\n\x1b[0m20:21:19  Found 3 models, 4 data tests, 1 source, 415 macros\n\x1b[0m20:21:19  \n\x1b[0m20:21:19  \n\x1b[0m20:21:19  Finished running  in 0 hours 0 minutes and 0.02 seconds (0.02s).\n\x1b[0m20:21:19  Encountered an error:\nRuntime Error\n  ERROR: Cross-db references not allowed in postgres (None vs prefect_server)\n', stderr='') 
[2024-07-24 17:21:20,779] INFO - prefect.CloudTaskRunner | FAIL signal raised: FAIL(None)
[2024-07-24 17:21:20,813] INFO - prefect.CloudTaskRunner | Task 'run_dbt': Finished task run for task with final state: 'Failed'
[2024-07-24 17:21:20,838] INFO - prefect.CloudTaskRunner | Task 'upload_logs_to_database': Starting task run...
[2024-07-24 17:21:20,864] INFO - prefect.upload_logs_to_database | 
 <> Falha ao conectar com o PostgreSQL: connection to server on socket "/var/run/postgresql/.s.PGSQL.5432" failed: No such file or directory
	Is the server running locally and accepting connections on that socket?

[2024-07-24 17:21:20,865] INFO - prefect.CloudTaskRunner | FAIL signal raised: FAIL(None)
[2024-07-24 17:21:20,887] INFO - prefect.CloudTaskRunner | Task 'upload_logs_to_database': Finished task run for task with final state: 'Failed'
[2024-07-24 17:21:20,905] INFO - prefect.CloudFlowRunner | Flow run FAILED: some reference tasks failed.
