[2024-07-24 03:50:11,547] INFO - prefect.clean_log_file | 
Limpeza do arquivo de log local logs.txt realizada com sucesso.
[2024-07-24 03:50:11,550] INFO - prefect.CloudTaskRunner | Task 'clean_log_file': Finished task run for task with final state: 'Success'
[2024-07-24 03:50:11,584] INFO - prefect.CloudTaskRunner | Task 'clean_log_file': Finished task run for task with final state: 'Success'
[2024-07-24 03:50:11,588] INFO - prefect.CloudTaskRunner | Task 'run_dbt': Starting task run...
[2024-07-24 03:50:11,632] INFO - prefect.CloudTaskRunner | Task 'run_dbt': Starting task run...
[2024-07-24 03:50:14,886] INFO - prefect.run_dbt | 
Falha na transformação (DBT):  CompletedProcess(args=['dbt', 'run', '--vars', 'database: None'], returncode=2, stdout='\x1b[0m06:50:13  Running with dbt=1.8.4\n\x1b[0m06:50:13  Registered adapter: postgres=1.8.2\n\x1b[0m06:50:13  [\x1b[33mWARNING\x1b[0m]: Configuration paths exist in your dbt_project.yml file which do not apply to any resources.\nThere are 2 unused configuration paths:\n- models.desafio_data_eng.marts\n- seeds.desafio_data_eng\n\x1b[0m06:50:13  Found 3 models, 2 data tests, 1 source, 415 macros\n\x1b[0m06:50:13  \n\x1b[0m06:50:13  \n\x1b[0m06:50:13  Finished running  in 0 hours 0 minutes and 0.02 seconds (0.02s).\n\x1b[0m06:50:13  Encountered an error:\nRuntime Error\n  ERROR: Cross-db references not allowed in postgres (None vs prefect_server)\n', stderr='') 
[2024-07-24 03:50:14,887] INFO - prefect.CloudTaskRunner | FAIL signal raised: FAIL(None)
[2024-07-24 03:50:14,927] INFO - prefect.CloudTaskRunner | Task 'run_dbt': Finished task run for task with final state: 'Failed'
[2024-07-24 03:50:14,961] INFO - prefect.CloudTaskRunner | Task 'upload_logs_to_database': Starting task run...
[2024-07-24 03:50:15,003] INFO - prefect.upload_logs_to_database | 
Falha ao conectar com o PostgreSQL: connection to server on socket "/var/run/postgresql/.s.PGSQL.5432" failed: No such file or directory
	Is the server running locally and accepting connections on that socket?

[2024-07-24 03:50:15,003] INFO - prefect.CloudTaskRunner | FAIL signal raised: FAIL(None)
[2024-07-24 03:50:15,035] INFO - prefect.CloudTaskRunner | Task 'upload_logs_to_database': Finished task run for task with final state: 'Failed'
[2024-07-24 03:50:15,061] INFO - prefect.CloudFlowRunner | Flow run FAILED: some reference tasks failed.
[2024-07-24 03:50:15,068] INFO - prefect.run_dbt | 
Falha na transformação (DBT):  CompletedProcess(args=['dbt', 'run', '--vars', 'database: None'], returncode=2, stdout='\x1b[0m06:50:13  Running with dbt=1.8.4\n\x1b[0m06:50:13  Registered adapter: postgres=1.8.2\n\x1b[0m06:50:13  [\x1b[33mWARNING\x1b[0m]: Configuration paths exist in your dbt_project.yml file which do not apply to any resources.\nThere are 2 unused configuration paths:\n- models.desafio_data_eng.marts\n- seeds.desafio_data_eng\n\x1b[0m06:50:13  Found 3 models, 2 data tests, 1 source, 415 macros\n\x1b[0m06:50:13  \n\x1b[0m06:50:13  \n\x1b[0m06:50:13  Finished running  in 0 hours 0 minutes and 0.02 seconds (0.02s).\n\x1b[0m06:50:13  Encountered an error:\nRuntime Error\n  ERROR: Cross-db references not allowed in postgres (None vs prefect_server)\n', stderr='') 
[2024-07-24 03:50:15,068] INFO - prefect.CloudTaskRunner | FAIL signal raised: FAIL(None)
[2024-07-24 03:50:15,106] INFO - prefect.CloudTaskRunner | Task 'run_dbt': Finished task run for task with final state: 'Failed'
[2024-07-24 03:50:15,138] INFO - prefect.CloudTaskRunner | Task 'upload_logs_to_database': Starting task run...
[2024-07-24 03:50:15,174] INFO - prefect.upload_logs_to_database | 
Falha ao conectar com o PostgreSQL: connection to server on socket "/var/run/postgresql/.s.PGSQL.5432" failed: No such file or directory
	Is the server running locally and accepting connections on that socket?

[2024-07-24 03:50:15,174] INFO - prefect.CloudTaskRunner | FAIL signal raised: FAIL(None)
[2024-07-24 03:50:15,210] INFO - prefect.CloudTaskRunner | Task 'upload_logs_to_database': Finished task run for task with final state: 'Failed'
[2024-07-24 03:50:15,234] INFO - prefect.CloudFlowRunner | Flow run FAILED: some reference tasks failed.
